<?xml version="1.0" encoding="utf-8"?>
<!-- =================================================================================== -->
<!-- |    This document was autogenerated by xacro from edo.urdf.xacro                 | -->
<!-- |    EDITING THIS FILE BY HAND IS NOT RECOMMENDED                                 | -->
<!-- =================================================================================== -->
<robot name="edo">
  <material name="Black">
    <color rgba="0.0 0.0 0.0 1.0"/>
  </material>
  <material name="Blue">
    <color rgba="0.0 0.0 0.8 1.0"/>
  </material>
  <material name="Green">
    <color rgba="0.0 0.8 0.0 1.0"/>
  </material>
  <material name="Grey">
    <color rgba="0.4 0.4 0.4 1.0"/>
  </material>
  <material name="Orange">
    <color rgba="1.0 0.423529411765 0.0392156862745 1.0"/>
  </material>
  <material name="Brown">
    <color rgba="0.870588235294 0.811764705882 0.764705882353 1.0"/>
  </material>
  <material name="Red">
    <color rgba="0.8 0.0 0.0 1.0"/>
  </material>
  <material name="White">
    <color rgba="1.0 1.0 1.0 1.0"/>
  </material>
  <!-- Fix to world just for testing -->
  <link name="world"/>
  <gazebo reference="world">
    <static>true</static>
  </gazebo>
  <!--joint between {parent} and base_link-->
  <joint name="world_edo_joint" type="fixed">
    <origin rpy="0 0 0" xyz="0 0 0"/>
    <parent link="world"/>
    <child link="edo_base_link"/>
  </joint>
  <link name="edo_base_link">
    <inertial>
      <origin rpy="0 0 0" xyz="0.057188 0.005983 0.05"/>
      <mass value="0.0785942338762368"/>
      <inertia ixx="0.0123841200738068" ixy="-0.000187984913202787" ixz="-1.32683892634308E-06" iyy="7.0169034503364E-05" iyz="-9.17416945099319E-05" izz="0.0123862261905614"/>
    </inertial>
    <visual>
      <origin rpy="0 0 0" xyz="0 0 0.135"/>
      <geometry>
        <mesh filename="package://edo_description/meshes/visual/link_0.dae"/>
      </geometry>
    </visual>
    <collision>
      <origin rpy="0 0 0" xyz="0 0 0.135"/>
      <geometry>
        <mesh filename="package://edo_description/meshes/collision/link_0.dae"/>
      </geometry>
      <material name="Grey"/>
    </collision>
  </link>
  <!-- joint between base_link and link_1 -->
  <joint name="edo_joint_1" type="revolute">
    <parent link="edo_base_link"/>
    <child link="edo_link_1"/>
    <origin rpy="0 0 0" xyz="0 0 0.337"/>
    <axis xyz="0 0 1"/>
    <!-- Joint limits of the real robot determined by jogging. TechSheet is wrong -->
    <limit effort="300" lower="-3.10668606855" upper="3.10668606855" velocity="1.5"/>
    <dynamics damping="0.5"/>
  </joint>
  <link name="edo_link_1">
    <inertial>
      <origin rpy="0 0 0" xyz="-0.037464 0.047260 0"/>
      <mass value="0.0785942338762368"/>
      <inertia ixx="0.0123841200738068" ixy="0.000187984913202727" ixz="-1.32683892634271E-06" iyy="7.01690345033622E-05" iyz="9.17416945099368E-05" izz="0.0123862261905615"/>
    </inertial>
    <visual>
      <origin rpy="0 0 0" xyz="0 0 0"/>
      <geometry>
        <mesh filename="package://edo_description/meshes/visual/link_1.dae"/>
      </geometry>
    </visual>
    <collision>
      <origin rpy="0 0 0" xyz="0 0 0"/>
      <geometry>
        <mesh filename="package://edo_description/meshes/collision/link_1.dae"/>
      </geometry>
      <material name="Orange"/>
    </collision>
  </link>
  <joint name="edo_joint_2" type="revolute">
    <parent link="edo_link_1"/>
    <child link="edo_link_2"/>
    <origin rpy="1.57079632679 0 0" xyz="0 0 0"/>
    <axis xyz="0 0 -1"/>
    <!-- Joint limits of the real robot determined by jogging. TechSheet is wrong -->
    <limit effort="300" lower="-1.71042266695" upper="1.71042266695" velocity="1.5"/>
    <dynamics damping="0.5"/>
  </joint>
  <link name="edo_link_2">
    <inertial>
      <origin rpy="0 0 0" xyz="-0.016423 0.031803 -0.045948"/>
      <mass value="0.0785942338762368"/>
      <inertia ixx="0.0122070242873091" ixy="0.000930596667670934" ixz="-0.0011486325666074" iyy="0.007576065624266" iyz="0.0059380539105297" izz="0.00505742538729646"/>
    </inertial>
    <visual>
      <origin rpy="1.57079632679 3.14159265359 3.14159265359" xyz="0 0.2105 0"/>
      <geometry>
        <mesh filename="package://edo_description/meshes/visual/link_2.dae"/>
      </geometry>
    </visual>
    <collision>
      <origin rpy="1.57079632679 3.14159265359 3.14159265359" xyz="0 0.2105 0"/>
      <geometry>
        <mesh filename="package://edo_description/meshes/collision/link_2.dae"/>
      </geometry>
      <material name="Orange"/>
    </collision>
  </link>
  <joint name="edo_joint_3" type="revolute">
    <parent link="edo_link_2"/>
    <child link="edo_link_3"/>
    <origin rpy="0 3.14159265359 3.14159265359" xyz="0 0.2105 0"/>
    <axis xyz="0 0 1"/>
    <!-- Joint limits of the real robot determined by jogging. TechSheet is wrong -->
    <limit effort="300" lower="-1.71042266695" upper="1.71042266695" velocity="1.5"/>
    <dynamics damping="0.5"/>
  </joint>
  <link name="edo_link_3">
    <inertial>
      <origin rpy="0 0 0" xyz="-0.031475 0.013100 0.000326"/>
      <mass value="0.0785942338762368"/>
      <inertia ixx="0.0123841200738068" ixy="0.000187984913202718" ixz="1.32683892634266E-06" iyy="7.01690345033619E-05" iyz="-9.17416945099381E-05" izz="0.0123862261905615"/>
    </inertial>
    <visual>
      <origin rpy="1.57079632679 0 0" xyz="0 0 0"/>
      <geometry>
        <mesh filename="package://edo_description/meshes/visual/link_3.dae"/>
      </geometry>
    </visual>
    <collision>
      <origin rpy="1.57079632679 0 0" xyz="0 0 0"/>
      <geometry>
        <mesh filename="package://edo_description/meshes/collision/link_3.dae"/>
      </geometry>
      <material name="Orange"/>
    </collision>
  </link>
  <joint name="edo_joint_4" type="revolute">
    <parent link="edo_link_3"/>
    <child link="edo_link_4"/>
    <origin rpy="1.57079632679 0 0" xyz="0 -0.268 0"/>
    <axis xyz="0 0 1"/>
    <!-- Joint limits of the real robot determined by jogging. TechSheet is wrong -->
    <limit effort="300" lower="-3.10668606855" upper="3.10668606855" velocity="1.5"/>
    <dynamics damping="0.5"/>
  </joint>
  <link name="edo_link_4">
    <inertial>
      <origin rpy="0 0 0" xyz="0.033909 0.000544 -0.013765"/>
      <mass value="0.0785942338762368"/>
      <inertia ixx="0.0123841200738068" ixy="-1.32683892634285E-06" ixz="0.000187984913202718" iyy="0.0123862261905615" iyz="9.17416945099506E-05" izz="7.01690345033621E-05"/>
    </inertial>
    <visual>
      <origin rpy="0 0 0" xyz="0 0 0"/>
      <geometry>
        <mesh filename="package://edo_description/meshes/visual/link_4.dae"/>
      </geometry>
    </visual>
    <collision>
      <origin rpy="0 0 0" xyz="0 0 0"/>
      <geometry>
        <mesh filename="package://edo_description/meshes/collision/link_4.dae"/>
      </geometry>
      <material name="Orange"/>
    </collision>
  </link>
  <joint name="edo_joint_5" type="revolute">
    <parent link="edo_link_4"/>
    <child link="edo_link_5"/>
    <origin rpy="0 0 0" xyz="0 0 0"/>
    <axis xyz="0 1 0"/>
    <!-- Joint limits of the real robot determined by jogging. TechSheet is wrong -->
    <limit effort="300" lower="-1.79768912955" upper="1.79768912955" velocity="1.5"/>
    <dynamics damping="0.5"/>
  </joint>
  <link name="edo_link_5">
    <inertial>
      <origin rpy="0 0 0" xyz="0.029485 -0.000458 0.026739"/>
      <mass value="0.0785942338762368"/>
      <inertia ixx="0.0123841200738068" ixy="1.32683892634191E-06" ixz="0.000187984913202582" iyy="0.0123862261905615" iyz="-9.17416945099552E-05" izz="7.01690345033581E-05"/>
    </inertial>
    <visual>
      <origin rpy="0 0 0" xyz="0 0 0"/>
      <geometry>
        <mesh filename="package://edo_description/meshes/visual/link_5.dae"/>
      </geometry>
    </visual>
    <collision>
      <origin rpy="0 0 0" xyz="0 0 0"/>
      <geometry>
        <mesh filename="package://edo_description/meshes/collision/link_5.dae"/>
      </geometry>
      <material name="Orange"/>
    </collision>
  </link>
  <joint name="edo_joint_6" type="revolute">
    <parent link="edo_link_5"/>
    <child link="edo_link_6"/>
    <origin rpy="0 0 0" xyz="0 0 0.1745"/>
    <axis xyz="0 0 1"/>
    <!-- MoveIt has problems with these huge limits -->
    <!--limit lower="${-2700 * PI / 180}" upper="${2700 * PI / 180}"
                   effort="${max_effort}" velocity="${max_velocity}" /-->
    <limit effort="300" lower="-4.71238898038" upper="4.71238898038" velocity="1.5"/>
    <dynamics damping="0.5"/>
  </joint>
  <link name="edo_link_6">
    <inertial>
      <origin rpy="0 0 0" xyz="0.000007 -0.009327 0.000006"/>
      <mass value="0.0279702497322662"/>
      <inertia ixx="7.63464744598253E-06" ixy="1.89204959067221E-10" ixz="5.32970316039599E-09" iyy="1.45744912344428E-05" iyz="1.08958003890421E-10" izz="7.62871791498103E-06"/>
    </inertial>
    <visual>
      <origin rpy="0 0 0" xyz="0 0 0"/>
      <geometry>
        <mesh filename="package://edo_description/meshes/visual/link_6.dae"/>
      </geometry>
    </visual>
    <collision>
      <origin rpy="0 0 0" xyz="0 0 0"/>
      <geometry>
        <mesh filename="package://edo_description/meshes/collision/link_6.dae"/>
      </geometry>
      <material name="Orange"/>
    </collision>
  </link>
  <joint name="edo_joint_ee" type="fixed">
    <parent link="edo_link_6"/>
    <child link="edo_link_ee"/>
    <origin rpy="0 0 0" xyz="0 0 0"/>
  </joint>
  <link name="edo_link_ee">
        </link>
  <!-- Load Gazebo lib and set the robot namespace -->
  <gazebo>
    <plugin filename="libgazebo_ros_control.so" name="gazebo_ros_control">
      <robotNamespace>/edo</robotNamespace>
    </plugin>
  </gazebo>
  <!-- Link0 -->
  <gazebo reference="edo_base_link">
    <mu1>0.2</mu1>
    <mu2>0.2</mu2>
  </gazebo>
  <!-- Link1 -->
  <gazebo reference="edo_link_1">
    <mu1>0.2</mu1>
    <mu2>0.2</mu2>
  </gazebo>
  <!-- Link2 -->
  <gazebo reference="edo_link_2">
    <mu1>0.2</mu1>
    <mu2>0.2</mu2>
  </gazebo>
  <!-- Link3 -->
  <gazebo reference="edo_link_3">
    <mu1>0.2</mu1>
    <mu2>0.2</mu2>
  </gazebo>
  <!-- Link4 -->
  <gazebo reference="edo_link_4">
    <mu1>0.2</mu1>
    <mu2>0.2</mu2>
  </gazebo>
  <!-- Link5 -->
  <gazebo reference="edo_link_5">
    <mu1>0.2</mu1>
    <mu2>0.2</mu2>
  </gazebo>
  <!-- Link6 -->
  <gazebo reference="edo_link_6">
    <mu1>0.2</mu1>
    <mu2>0.2</mu2>
  </gazebo>
  <transmission name="edo_tran_1">
    <robotNamespace>/edo</robotNamespace>
    <type>transmission_interface/SimpleTransmission</type>
    <joint name="edo_joint_1">
      <hardwareInterface>hardware_interface/PositionJointInterface</hardwareInterface>
    </joint>
    <actuator name="edo_motor_1">
      <hardwareInterface>hardware_interface/PositionJointInterface</hardwareInterface>
      <mechanicalReduction>1</mechanicalReduction>
    </actuator>
  </transmission>
  <transmission name="edo_tran_2">
    <robotNamespace>/edo</robotNamespace>
    <type>transmission_interface/SimpleTransmission</type>
    <joint name="edo_joint_2">
      <hardwareInterface>hardware_interface/PositionJointInterface</hardwareInterface>
    </joint>
    <actuator name="edo_motor_2">
      <hardwareInterface>hardware_interface/PositionJointInterface</hardwareInterface>
      <mechanicalReduction>1</mechanicalReduction>
    </actuator>
  </transmission>
  <transmission name="edo_tran_3">
    <robotNamespace>/edo</robotNamespace>
    <type>transmission_interface/SimpleTransmission</type>
    <joint name="edo_joint_3">
      <hardwareInterface>hardware_interface/PositionJointInterface</hardwareInterface>
    </joint>
    <actuator name="edo_motor_3">
      <hardwareInterface>hardware_interface/PositionJointInterface</hardwareInterface>
      <mechanicalReduction>1</mechanicalReduction>
    </actuator>
  </transmission>
  <transmission name="edo_tran_4">
    <robotNamespace>/edo</robotNamespace>
    <type>transmission_interface/SimpleTransmission</type>
    <joint name="edo_joint_4">
      <hardwareInterface>hardware_interface/PositionJointInterface</hardwareInterface>
    </joint>
    <actuator name="edo_motor_4">
      <hardwareInterface>hardware_interface/PositionJointInterface</hardwareInterface>
      <mechanicalReduction>1</mechanicalReduction>
    </actuator>
  </transmission>
  <transmission name="edo_tran_5">
    <robotNamespace>/edo</robotNamespace>
    <type>transmission_interface/SimpleTransmission</type>
    <joint name="edo_joint_5">
      <hardwareInterface>hardware_interface/PositionJointInterface</hardwareInterface>
    </joint>
    <actuator name="edo_motor_5">
      <hardwareInterface>hardware_interface/PositionJointInterface</hardwareInterface>
      <mechanicalReduction>1</mechanicalReduction>
    </actuator>
  </transmission>
  <transmission name="edo_tran_6">
    <robotNamespace>/edo</robotNamespace>
    <type>transmission_interface/SimpleTransmission</type>
    <joint name="edo_joint_6">
      <hardwareInterface>hardware_interface/PositionJointInterface</hardwareInterface>
    </joint>
    <actuator name="edo_motor_6">
      <hardwareInterface>hardware_interface/PositionJointInterface</hardwareInterface>
      <mechanicalReduction>1</mechanicalReduction>
    </actuator>
  </transmission>
</robot>
